Workbook

Sheet Painel de Vagas BCK 18MAI
A1: COD | B1: VAGAS | C1: DATA DE ABERTURA DA VAGA | D1: DIAS ABERTA | E1: CRITICIDADE | F1: SERVIÇO | G1: RECRUTADOR | H1: STATUS RECRUTADOR | I1: STATUS GERAL | J1: CARGO | K1: SUPERVISÃO | L1: CLIENTE | M1: LOCALIDADE | N1: TURNO | O1: ESCALA | P1: JORNADA | Q1: COMENTÁRIOS RECRUTADOR | R1: FONTE DE CAPTAÇÃO | S1: TELFONE | T1: RESPONSÁVEL | U1: DATA DE RECEBIMENTO | V1: NOME DO CANDIDATO | W1: STATUS DOCUMENTAÇÃO | X1: INTEGRAÇÃO | Y1: ADMISSÃO | Z1: RE | AA1: COMENTÁRIOS E OBSERVAÇÕES | AB1: DESISTÊNCIAS
A2: 28789 | B2: 1 | C2: 46048 | D2: =TODAY()-C2 -> 179 | E2: =IF(W2="ADMITIDO","ADMITIDO",IF(W2="CANCELADA","CANCELADA",IF(H2="","",IF(H2="ADMITIDO","ADMITIDO",IF(H2="CANCELADA","CANCELADA",IF(OR(H2="ANALISE CANCELAMENTO",H2="ANÁLISE CANCELAMENTO"),"EM ANÁLISE",IF(D2="","",IF(D2<=7,"NO PRAZO",IF(D2<=14,"ATENÇÃO","CRÍTICO"))))))))) -> ADMITIDO | F2: SEGURANÇA | G2: ELONY | H2: =W2 -> ADMITIDO | I2: =IF(W2="ADMITIDO","ADMITIDO",IF(W2="CANCELADA","CANCELADA",IF(H2="","",IFERROR(_xlfn.XLOOKUP(H2,Listas!I:I,Listas!J:J),"OUTROS")))) -> ADMITIDO | J2: VIGIA 6 | K2: MARCELO RODRIGUES CARUNCHO CARNAVAL | L2: CAMPINAS3 - RESERVA TECNICA - SEGURANCA | M2: RESERVAS | N2: DIURNO | O2: 12X36 | P2: 12H - 06:00 - 18:00 C/ 1H INTERV | Q2: Vaga da Bruna / Houveram 2 desistências - passada Elony dia 20/04 | T2: ANA | U2: 46142 | V2: WAGNER BENEDITO DA SILVA | W2: ADMITIDO | X2: 46150 | Y2: 46151 | Z2: 914242 | AA2: Candidato - JULIO CEZAR DE OLIVEIRA CAMISA desistiu no dia 28/04 | AB2: 0
A3: 28991 | B3: 1 | C3: 46063 | D3: =TODAY()-C3 -> 164 | E3: =IF(W3="ADMITIDO","ADMITIDO",IF(W3="CANCELADA","CANCELADA",IF(H3="","",IF(H3="ADMITIDO","ADMITIDO",IF(H3="CANCELADA","CANCELADA",IF(OR(H3="ANALISE CANCELAMENTO",H3="ANÁLISE CANCELAMENTO"),"EM ANÁLISE",IF(D3="","",IF(D3<=7,"NO PRAZO",IF(D3<=14,"ATENÇÃO","CRÍTICO"))))))))) -> ADMITIDO | F3: FACILITIES | G3: FREITAS | H3: =W3 -> ADMITIDO | I3: =IF(W3="ADMITIDO","ADMITIDO",IF(W3="CANCELADA","CANCELADA",IF(H3="","",IFERROR(_xlfn.XLOOKUP(H3,Listas!I:I,Listas!J:J),"OUTROS")))) -> ADMITIDO | J3: AUXILIAR DE SERVIÇOS GERAIS | K3: KELLY ROBERTA FRATUCCI | L3: PROMAX BARDAHL | M3: CAJAMAR | N3: DIURNO | O3: 5X2 FOLGA SÁB/DOM/FER | P3: 09:48H - 06:00 - 15:48 C/ 1H INTERV | T3: ROSI | U3: 46126 | V3: Paulo Henrique | W3: ADMITIDO | X3: 46134 | Y3: 46135 | Z3: 914145 | AB3: 0
A4: 29028 | B4: 1 | C4: 46065 | D4: =TODAY()-C4 -> 162 | E4: =IF(W4="ADMITIDO","ADMITIDO",IF(W4="CANCELADA","CANCELADA",IF(H4="","",IF(H4="ADMITIDO","ADMITIDO",IF(H4="CANCELADA","CANCELADA",IF(OR(H4="ANALISE CANCELAMENTO",H4="ANÁLISE CANCELAMENTO"),"EM ANÁLISE",IF(D4="","",IF(D4<=7,"NO PRAZO",IF(D4<=14,"ATENÇÃO","CRÍTICO"))))))))) -> CANCELADA | F4: FACILITIES | G4: ELONY | H4: CANCELADA | I4: =IF(W4="ADMITIDO","ADMITIDO",IF(W4="CANCELADA","CANCELADA",IF(H4="","",IFERROR(_xlfn.XLOOKUP(H4,Listas!I:I,Listas!J:J),"OUTROS")))) -> CANCELADA | J4: AUXILIAR DE LIMPEZA | K4: ELIANA MARIA MOREIRA BRANSANI | L4: CAMPINAS5 - RESERVA TECNICA - FACILITIES | M4: RESERVAS | N4: NOTURNO | O4: 6X1 FOLGA DOM/FER | P4: 08:20H - 22:00 - 06:20 C/ 1H INTERV | Q4: Enviado email 20/04 - Eliana para confirmar cancelamento, confirmado cancelamento email 22/04 | W4: CANCELADA | AB4: 0
A5: 29493 | B5: 1 | C5: 46104 | D5: =TODAY()-C5 -> 123 | E5: =IF(W5="ADMITIDO","ADMITIDO",IF(W5="CANCELADA","CANCELADA",IF(H5="","",IF(H5="ADMITIDO","ADMITIDO",IF(H5="CANCELADA","CANCELADA",IF(OR(H5="ANALISE CANCELAMENTO",H5="ANÁLISE CANCELAMENTO"),"EM ANÁLISE",IF(D5="","",IF(D5<=7,"NO PRAZO",IF(D5<=14,"ATENÇÃO","CRÍTICO"))))))))) -> ADMITIDO | F5: FACILITIES | G5: NATHALYA | H5: ADMITIDO | I5: =IF(W5="ADMITIDO","ADMITIDO",IF(W5="CANCELADA","CANCELADA",IF(H5="","",IFERROR(_xlfn.XLOOKUP(H5,Listas!I:I,Listas!J:J),"OUTROS")))) -> ADMITIDO | J5: AUXILIAR DE LIMPEZA | K5: MAIARA RODRIGUES DE ANDRADE COSTA | L5: THE ONE OFFICE | M5: JUNDIAÍ | N5: DIURNO | O5: 6X1 FOLGA DOM/FER | P5: 09H - 12:00-21:00 C/ INT SEG-SEX/04H SAB | R5: WHATSAPP | S5: 11 97375-0776 | T5: PATRICIA | U5: 46134 | V5: RAISSA APARECIDA JESUS | W5: ADMITIDO | X5: 46146 | Y5: 46147 | Z5: 145905 | AB5: 0
A6: 29199 | B6: 1 | C6: 46080 | D6: =TODAY()-C6 -> 147 | E6: =IF(W6="ADMITIDO","ADMITIDO",IF(W6="CANCELADA","CANCELADA",IF(H6="","",IF(H6="ADMITIDO","ADMITIDO",IF(H6="CANCELADA","CANCELADA",IF(OR(H6="ANALISE CANCELAMENTO",H6="ANÁLISE CANCELAMENTO"),"EM ANÁLISE",IF(D6="","",IF(D6<=7,"NO PRAZO",IF(D6<=14,"ATENÇÃO","CRÍTICO"))))))))) -> ADMITIDO | F6: FACILITIES | G6: GIOVANNA | H6: ADMITIDO | I6: =IF(W6="ADMITIDO","ADMITIDO",IF(W6="CANCELADA","CANCELADA",IF(H6="","",IFERROR(_xlfn.XLOOKUP(H6,Listas!I:I,Listas!J:J),"OUTROS")))) -> ADMITIDO | J6: AUXILIAR DE LIMPEZA | K6: MIGUEL GIOSA PIVA | L6: FACILITIES2 - RESERVA TECNICA | M6: RESERVAS | N6: DIURNO | O6: 6X1 TROCA SÁB/DOM FOLGA FER | P6: 09H - 07:00-16:00 C/INT SEG- SEX/04H S/D | R6: WHATSAPP | S6: +55 11 95146-6912 | T6: PATRICIA | U6: 46134 | V6: SARA PASSOS GARCIA | W6: ADMITIDO | X6: 46146 | Y6: 46147 | Z6: 145909 | AB6: 0
B7: 1 | C7: 46080 | D7: =TODAY()-C7 -> 147 | E7: =IF(W7="ADMITIDO","ADMITIDO",IF(W7="CANCELADA","CANCELADA",IF(H7="","",IF(H7="ADMITIDO","ADMITIDO",IF(H7="CANCELADA","CANCELADA",IF(OR(H7="ANALISE CANCELAMENTO",H7="ANÁLISE CANCELAMENTO"),"EM ANÁLISE",IF(D7="","",IF(D7<=7,"NO PRAZO",IF(D7<=14,"ATENÇÃO","CRÍTICO"))))))))) -> ADMITIDO | F7: FACILITIES | G7: GIOVANNA | H7: ADMITIDO | I7: =IF(W7="ADMITIDO","ADMITIDO",IF(W7="CANCELADA","CANCELADA",IF(H7="","",IFERROR(_xlfn.XLOOKUP(H7,Listas!I:I,Listas!J:J),"OUTROS")))) -> ADMITIDO | J7: AUXILIAR DE LIMPEZA | K7: MIGUEL GIOSA PIVA | L7: FACILITIES2 - RESERVA TECNICA | M7: RESERVAS | N7: DIURNO | O7: 6X1 TROCA SÁB/DOM FOLGA FER | P7: 09H - 07:00-16:00 C/INT SEG- SEX/04H S/D | R7: WHATSAPP | T7: RITA | U7: 46141 | V7: PATRICIA APARECIDA DE CARVALHO | W7: ADMITIDO | X7: 46147 | Y7: 46148 | Z7: 145918 | AB7: 0
A8: 29200 | B8: 1 | C8: 46080 | D8: =TODAY()-C8 -> 147 | E8: =IF(W8="ADMITIDO","ADMITIDO",IF(W8="CANCELADA","CANCELADA",IF(H8="","",IF(H8="ADMITIDO","ADMITIDO",IF(H8="CANCELADA","CANCELADA",IF(OR(H8="ANALISE CANCELAMENTO",H8="ANÁLISE CANCELAMENTO"),"EM ANÁLISE",IF(D8="","",IF(D8<=7,"NO PRAZO",IF(D8<=14,"ATENÇÃO","CRÍTICO"))))))))) -> ADMITIDO | F8: FACILITIES | G8: GIOVANNA | H8: ADMITIDO | I8: =IF(W8="ADMITIDO","ADMITIDO",IF(W8="CANCELADA","CANCELADA",IF(H8="","",IFERROR(_xlfn.XLOOKUP(H8,Listas!I:I,Listas!J:J),"OUTROS")))) -> ADMITIDO | J8: AUXILIAR DE LIMPEZA | K8: MIGUEL GIOSA PIVA | L8: MAESTRAL COML. | M8: JUNDIAÍ | N8: DIURNO | O8: 5X2 FOLGA SÁB/DOM/FER | P8: 09:48H - 08:00 - 17:48 C/ 1H INTERV | Q8: Desistência de candidatos | R8: PAT JUNDIAI | S8: 11 97390-5487 | T8: PATRICIA | U8: 46149 | V8: MARCOS ALBERTO FERNANDES | W8: ADMITIDO | X8: 46154 | Y8: 46156 | Z8: 145950 | AA8: JOSÉ LUEDSON VIEIRA DA SILVA - Integração foi agendada mas não compareceu e não retornou | AB8: 0
A9: 29288 | B9: 1 | C9: 46086 | D9: =TODAY()-C9 -> 141 | E9: =IF(W9="ADMITIDO","ADMITIDO",IF(W9="CANCELADA","CANCELADA",IF(H9="","",IF(H9="ADMITIDO","ADMITIDO",IF(H9="CANCELADA","CANCELADA",IF(OR(H9="ANALISE CANCELAMENTO",H9="ANÁLISE CANCELAMENTO"),"EM ANÁLISE",IF(D9="","",IF(D9<=7,"NO PRAZO",IF(D9<=14,"ATENÇÃO","CRÍTICO"))))))))) -> ADMITIDO | F9: SEGURANÇA | G9: ELONY | H9: =W9 -> ADMITIDO | I9: =IF(W9="ADMITIDO","ADMITIDO",IF(W9="CANCELADA","CANCELADA",IF(H9="","",IFERROR(_xlfn.XLOOKUP(H9,Listas!I:I,Listas!J:J),"OUTROS")))) -> ADMITIDO | J9: VIGIA 22 | K9: THAIS FERNANDA TOZZI | L9: CANON MEDICAL SYSTEMS DO BRASIL LTDA - CAMPINAS | M9: CAMPINAS | N9: DIURNO | O9: 5X2 FOLGA SÁB/DOM/FER | P9: 10H - 09:00 - 18:00 C/ 1H INTERV | T9: ANA | U9: 46127 | V9: ANA PAULA GONÇALVES TIGRE | W9: ADMITIDO | X9: 46139 | Y9: 46130 | Z9: 914174 | AB9: 0
A10: 29258 | B10: 1 | C10: 46086 | D10: =TODAY()-C10 -> 141 | E10: =IF(W10="ADMITIDO","ADMITIDO",IF(W10="CANCELADA","CANCELADA",IF(H10="","",IF(H10="ADMITIDO","ADMITIDO",IF(H10="CANCELADA","CANCELADA",IF(OR(H10="ANALISE CANCELAMENTO",H10="ANÁLISE CANCELAMENTO"),"EM ANÁLISE",IF(D10="","",IF(D10<=7,"NO PRAZO",IF(D10<=14,"ATENÇÃO","CRÍTICO"))))))))) -> CRÍTICO | F10: FACILITIES | G10: ELONY | H10: TRIAGEM 1 | I10: =IF(W10="ADMITIDO","ADMITIDO",IF(W10="CANCELADA","CANCELADA",IF(H10="","",IFERROR(_xlfn.XLOOKUP(H10,Listas!I:I,Listas!J:J),"OUTROS")))) -> TRIAGEM | J10: AUXILIAR DE LIMPEZA | K10: ELIANA MARIA MOREIRA BRANSANI | L10: NEO RODAS - VINHEDO | M10: VINHEDO | N10: DIURNO | O10: 6X1 FOLGA DOM/FER | P10: 08:20H - 13:40 - 22:00 C/ 1H INTERV | S10: 19 99536 9183 | AB10: 0
A11: 29270 | B11: 1 | C11: 46086 | D11: =TODAY()-C11 -> 141 | E11: =IF(W11="ADMITIDO","ADMITIDO",IF(W11="CANCELADA","CANCELADA",IF(H11="","",IF(H11="ADMITIDO","ADMITIDO",IF(H11="CANCELADA","CANCELADA",IF(OR(H11="ANALISE CANCELAMENTO",H11="ANÁLISE CANCELAMENTO"),"EM ANÁLISE",IF(D11="","",IF(D11<=7,"NO PRAZO",IF(D11<=14,"ATENÇÃO","CRÍTICO"))))))))) -> ADMITIDO | F11: FACILITIES | G11: FREITAS | H11: ADMITIDO | I11: =IF(W11="ADMITIDO","ADMITIDO",IF(W11="CANCELADA","CANCELADA",IF(H11="","",IFERROR(_xlfn.XLOOKUP(H11,Listas!I:I,Listas!J:J),"OUTROS")))) -> ADMITIDO | J11: AUXILIAR DE SERVIÇOS GERAIS | K11: KELLY ROBERTA FRATUCCI | L11: URBAN PACAEMBU | M11: SÃO PAULO | N11: DIURNO | O11: 6X1 FOLGA DOM/FER | P11: 09H - 07:00-16:00 C/INT SEG- SEX/04H SAB | Q11: 27/04 - Cristian não compareceu na integração por 2x | S11: 11960178856 | T11: ROSI | U11: 46140 | V11: RICHARD THIAGO ARNAIS DA SILVA | W11: ADMITIDO | X11: 46148 | Y11: 46148 | Z11: 914215 | AA11: Vai comparecer amanhã (07/05) | AB11: 0
A12: 29345 | B12: 1 | C12: 46091 | D12: =TODAY()-C12 -> 136 | E12: =IF(W12="ADMITIDO","ADMITIDO",IF(W12="CANCELADA","CANCELADA",IF(H12="","",IF(H12="ADMITIDO","ADMITIDO",IF(H12="CANCELADA","CANCELADA",IF(OR(H12="ANALISE CANCELAMENTO",H12="ANÁLISE CANCELAMENTO"),"EM ANÁLISE",IF(D12="","",IF(D12<=7,"NO PRAZO",IF(D12<=14,"ATENÇÃO","CRÍTICO"))))))))) -> ADMITIDO | F12: FACILITIES | G12: WILLIAM | H12: =W12 -> ADMITIDO | I12: =IF(W12="ADMITIDO","ADMITIDO",IF(W12="CANCELADA","CANCELADA",IF(H12="","",IFERROR(_xlfn.XLOOKUP(H12,Listas!I:I,Listas!J:J),"OUTROS")))) -> ADMITIDO | J12: AUXILIAR DE LIMPEZA | K12: CRISTIANE APARECIDA VIANA DA SILVA | L12: FACILITIES3 - RESERVA TECNICA | M12: RESERVAS | N12: DIURNO | O12: 6X1 FOLGA DOM/FER | P12: 08:00H - 14:00 - 22:00 C/ 1H INTERV | Q12: Cand Jhoni desistiu/ Cbadidata Maria desistiu/ cand. Reginaldo em documentação, desisitiu dia 08/05| Pedro aprovado 11/05| | R12: RECEPTIVO NO WHATSAPP | S12: 11 94385-3802 | T12: LUANA | U12: 46153 | V12: PEDRO AUGUSTO DA SILVA COSTA | W12: ADMITIDO | X12: 46154 | Y12: 46155 | Z12: 145951 | AA12: MARIA APARECIDA MENDES DE SOUZA Exame agendado para o dia 29/04, porém ela não compareceu. Solicitou reagendamento e também não compareceu. Tentativas de contato sem sucesso. REGINALDO RODRIGUES DE LIMA Recebido dia 06/05 declinou por não quer mais a vaga dia 08/05, não realizou ASO | AB12: 0
A13: 29385 | B13: 1 | C13: 46093 | D13: =TODAY()-C13 -> 134 | E13: =IF(W13="ADMITIDO","ADMITIDO",IF(W13="CANCELADA","CANCELADA",IF(H13="","",IF(H13="ADMITIDO","ADMITIDO",IF(H13="CANCELADA","CANCELADA",IF(OR(H13="ANALISE CANCELAMENTO",H13="ANÁLISE CANCELAMENTO"),"EM ANÁLISE",IF(D13="","",IF(D13<=7,"NO PRAZO",IF(D13<=14,"ATENÇÃO","CRÍTICO"))))))))) -> CANCELADA | F13: FACILITIES | G13: NATHALYA | H13: CANCELADA | I13: =IF(W13="ADMITIDO","ADMITIDO",IF(W13="CANCELADA","CANCELADA",IF(H13="","",IFERROR(_xlfn.XLOOKUP(H13,Listas!I:I,Listas!J:J),"OUTROS")))) -> CANCELADA | J13: AUXILIAR DE LIMPEZA | K13: MAIARA RODRIGUES DE ANDRADE COSTA | L13: PASARGADA | M13: JUNDIAÍ | N13: DIURNO | O13: 6X1 TROCA SÁB/DOM FOLGA FER | P13: 09H -07:00-16:00 C/INT SEG- SEX/04H S/D. | Q13: CANDIDATA SIMONE APROVADA 30/03 (Desistiu da vaga) - CANDIDATA LUCIANA APROVADA 09/04 (Declinada por falta de documentos) CNAD MARIANA DO WILLIAM 29/04 | W13: CANCELADA | AA13: MARIANA GOMES: Declinou 30/04 | AB13: 0
A14: 29310 | B14: 1 | C14: 46093 | D14: =TODAY()-C14 -> 134 | E14: =IF(W14="ADMITIDO","ADMITIDO",IF(W14="CANCELADA","CANCELADA",IF(H14="","",IF(H14="ADMITIDO","ADMITIDO",IF(H14="CANCELADA","CANCELADA",IF(OR(H14="ANALISE CANCELAMENTO",H14="ANÁLISE CANCELAMENTO"),"EM ANÁLISE",IF(D14="","",IF(D14<=7,"NO PRAZO",IF(D14<=14,"ATENÇÃO","CRÍTICO"))))))))) -> ADMITIDO | F14: FACILITIES | G14: NATHALYA | H14: =W14 -> ADMITIDO | I14: =IF(W14="ADMITIDO","ADMITIDO",IF(W14="CANCELADA","CANCELADA",IF(H14="","",IFERROR(_xlfn.XLOOKUP(H14,Listas!I:I,Listas!J:J),"OUTROS")))) -> ADMITIDO | J14: JARDINEIRO 2 | K14: LINDBERG TUMOLO | L14: VOLANTES - SERVICO EXTRA | M14: ADM | N14: DIURNO | O14: 5X2 FOLGA SÁB/DOM/FER | P14: 09:48H - 07:00 - 16:48 C/ 1H INTERV | Q14: CANDIDATO CLEBEERTON APROVADO 08/04 (Declinado por ser ex-funcionário, não informou durante a entrevista e não foi autorizado seu retorno) - CANDIDATO CHRISTOFER APROVADO 16/04 | R14: WHATSAPP | S14: 11 93280-6857 | T14: RITA | U14: 46128 | V14: CHRISTOFER BARBOSA ROCHA | W14: ADMITIDO | X14: 46132 | Y14: 46135 | Z14: 914147 | AA14: Problema com documentos | AB14: 0
A15: 29310 | B15: 1 | C15: 46093 | D15: =TODAY()-C15 -> 134 | E15: =IF(W15="ADMITIDO","ADMITIDO",IF(W15="CANCELADA","CANCELADA",IF(H15="","",IF(H15="ADMITIDO","ADMITIDO",IF(H15="CANCELADA","CANCELADA",IF(OR(H15="ANALISE CANCELAMENTO",H15="ANÁLISE CANCELAMENTO"),"EM ANÁLISE",IF(D15="","",IF(D15<=7,"NO PRAZO",IF(D15<=14,"ATENÇÃO","CRÍTICO"))))))))) -> ADMITIDO | F15: FACILITIES | G15: NATHALYA | H15: =W15 -> ADMITIDO | I15: =IF(W15="ADMITIDO","ADMITIDO",IF(W15="CANCELADA","CANCELADA",IF(H15="","",IFERROR(_xlfn.XLOOKUP(H15,Listas!I:I,Listas!J:J),"OUTROS")))) -> ADMITIDO | J15: JARDINEIRO 2 | K15: LINDBERG TUMOLO | L15: VOLANTES - SERVICO EXTRA | M15: ADM | N15: DIURNO | O15: 5X2 FOLGA SÁB/DOM/FER | P15: 09:48H - 07:00 - 16:48 C/ 1H INTERV | R15: WHATSAPP | S15: 11 92173-6036 | T15: RITA | U15: 46135 | V15: CLEBERTON APARECIDO | W15: ADMITIDO | X15: 46140 | Y15: 46141 | Z15: 914178 | AA15: INTEGRAÇÃO DO DIA 27/04 FOI REMANEJADA A PEDIDO DO CANDIDATO PARA O DIA 28/04 | AB15: 0
A16: 29420 | B16: 1 | C16: 46097 | D16: =TODAY()-C16 -> 130 | E16: =IF(W16="ADMITIDO","ADMITIDO",IF(W16="CANCELADA","CANCELADA",IF(H16="","",IF(H16="ADMITIDO","ADMITIDO",IF(H16="CANCELADA","CANCELADA",IF(OR(H16="ANALISE CANCELAMENTO",H16="ANÁLISE CANCELAMENTO"),"EM ANÁLISE",IF(D16="","",IF(D16<=7,"NO PRAZO",IF(D16<=14,"ATENÇÃO","CRÍTICO"))))))))) -> CANCELADA | F16: FACILITIES | G16: GIOVANNA | H16: CANCELADA | I16: =IF(W16="ADMITIDO","ADMITIDO",IF(W16="CANCELADA","CANCELADA",IF(H16="","",IFERROR(_xlfn.XLOOKUP(H16,Listas!I:I,Listas!J:J),"OUTROS")))) -> CANCELADA | J16: AUXILIAR DE SERVIÇOS GERAIS | K16: MIGUEL GIOSA PIVA | L16: CAMINHOS DA SERRA 3 | M16: JUNDIAÍ | N16: DIURNO | O16: 6X1 FOLGA DOM/FER | P16: 09H - 07:00-16:00 C/INT SEG- SEX/04H SAB | Q16: A colaboradora VÂNIA foi remanejada para outro contrato | W16: CANCELADA | AB16: 0
A17: 29417 | B17: 1 | C17: 46097 | D17: =TODAY()-C17 -> 130 | E17: =IF(W17="ADMITIDO","ADMITIDO",IF(W17="CANCELADA","CANCELADA",IF(H17="","",IF(H17="ADMITIDO","ADMITIDO",IF(H17="CANCELADA","CANCELADA",IF(OR(H17="ANALISE CANCELAMENTO",H17="ANÁLISE CANCELAMENTO"),"EM ANÁLISE",IF(D17="","",IF(D17<=7,"NO PRAZO",IF(D17<=14,"ATENÇÃO","CRÍTICO"))))))))) -> ADMITIDO | F17: FACILITIES | G17: GIOVANNA | H17: ADMITIDO | I17: =IF(W17="ADMITIDO","ADMITIDO",IF(W17="CANCELADA","CANCELADA",IF(H17="","",IFERROR(_xlfn.XLOOKUP(H17,Listas!I:I,Listas!J:J),"OUTROS")))) -> ADMITIDO | J17: AUXILIAR DE LIMPEZA | K17: MIGUEL GIOSA PIVA | L17: HORIBA | M17: JUNDIAÍ | N17: DIURNO | O17: 5X2 FOLGA SÁB/DOM/FER | P17: 09:48H - 07:00 - 16:48 C/ INTERV | R17: WHATSAPP | T17: BEATRIZ | U17: 46150 | V17: ANDREIA DO CARMO DE JESUS | W17: ADMITIDO | X17: 46156 | Y17: 46160 | Z17: 914285 | AA17: Candidata Claudinéia declinou da vaga em 28/04 - vaga reabera / LUCIANA FERREIRA: Declinamos por falta de retorno 04.05 | AB17: 0
A18: 29444 | B18: 1 | C18: 46098 | D18: =TODAY()-C18 -> 129 | E18: =IF(W18="ADMITIDO","ADMITIDO",IF(W18="CANCELADA","CANCELADA",IF(H18="","",IF(H18="ADMITIDO","ADMITIDO",IF(H18="CANCELADA","CANCELADA",IF(OR(H18="ANALISE CANCELAMENTO",H18="ANÁLISE CANCELAMENTO"),"EM ANÁLISE",IF(D18="","",IF(D18<=7,"NO PRAZO",IF(D18<=14,"ATENÇÃO","CRÍTICO"))))))))) -> ADMITIDO | F18: FACILITIES | G18: WILLIAM | H18: =W18 -> ADMITIDO | I18: =IF(W18="ADMITIDO","ADMITIDO",IF(W18="CANCELADA","CANCELADA",IF(H18="","",IFERROR(_xlfn.XLOOKUP(H18,Listas!I:I,Listas!J:J),"OUTROS")))) -> ADMITIDO | J18: AUXILIAR DE SERVIÇOS GERAIS | K18: CRISTIANE APARECIDA VIANA DA SILVA | L18: FACILITIES3 - RESERVA TECNICA | M18: RESERVAS | N18: DIURNO | O18: 6X1 FOLGA DOM/FER | P18: 09H - 07:00-16:00 C/INT SEG- SEX/04H SAB | Q18: CANDIDATA MARIA APARECIDA APROVADA DESISTIU / IGOR aprovado 06/05 não deu mais retorno| CANDIDATO LUCAS APROVADO 08/05 FECHADO PELA NATHALYA | R18: RECEPTIVO NO WHATSAPP | S18: 119 7521-3162 | T18: BEATRIZ | U18: 46150 | V18: LUCAS VINICIUS MENDES DOS SANTOS | W18: ADMITIDO | X18: 46154 | Y18: 46155 | Z18: 145949 | AA18: IGOR SANTOS - Atraso para subir , devido falta de documentos . Feito cadastro desistiu da vaga | AB18: 0
A19: 29429 | B19: 1 | C19: 46098 | D19: =TODAY()-C19 -> 129 | E19: =IF(W19="ADMITIDO","ADMITIDO",IF(W19="CANCELADA","CANCELADA",IF(H19="","",IF(H19="ADMITIDO","ADMITIDO",IF(H19="CANCELADA","CANCELADA",IF(OR(H19="ANALISE CANCELAMENTO",H19="ANÁLISE CANCELAMENTO"),"EM ANÁLISE",IF(D19="","",IF(D19<=7,"NO PRAZO",IF(D19<=14,"ATENÇÃO","CRÍTICO"))))))))) -> ADMITIDO | F19: FACILITIES | G19: WILLIAM | H19: ADMITIDO | I19: =IF(W19="ADMITIDO","ADMITIDO",IF(W19="CANCELADA","CANCELADA",IF(H19="","",IFERROR(_xlfn.XLOOKUP(H19,Listas!I:I,Listas!J:J),"OUTROS")))) -> ADMITIDO | J19: AUXILIAR DE LIMPEZA | K19: MAIARA RODRIGUES DE ANDRADE COSTA | L19: FACILITIES7 - RESERVA DELPHOS | M19: RESERVAS | N19: DIURNO | O19: 6X1 FOLGA DOM/FER | P19: 09H - 07:00-16:00 C/INT SEG- SEX/04H S/D | Q19: CANDIDATA ALYCIA EM PESQUISA 08/05 - CANDIDATA ALYCIA APROVADA 11/05 | R19: INDIQUE UM AMIGO | S19: 11 95585-2637 | T19: PATRICIA | V19: FRANCISCO PELE DE MOURA | W19: ADMITIDO | X19: 46148 | Y19: 46149 | Z19: 145923 | AB19: 0
A20: 29429 | B20: 1 | C20: 46098 | D20: =TODAY()-C20 -> 129 | E20: =IF(W20="ADMITIDO","ADMITIDO",IF(W20="CANCELADA","CANCELADA",IF(H20="","",IF(H20="ADMITIDO","ADMITIDO",IF(H20="CANCELADA","CANCELADA",IF(OR(H20="ANALISE CANCELAMENTO",H20="ANÁLISE CANCELAMENTO"),"EM ANÁLISE",IF(D20="","",IF(D20<=7,"NO PRAZO",IF(D20<=14,"ATENÇÃO","CRÍTICO"))))))))) -> ADMITIDO | F20: FACILITIES | G20: NATHALYA | H20: ADMITIDO | I20: =IF(W20="ADMITIDO","ADMITIDO",IF(W20="CANCELADA","CANCELADA",IF(H20="","",IFERROR(_xlfn.XLOOKUP(H20,Listas!I:I,Listas!J:J),"OUTROS")))) -> ADMITIDO | J20: AUXILIAR DE LIMPEZA | K20: MAIARA RODRIGUES DE ANDRADE COSTA | L20: FACILITIES7 - RESERVA DELPHOS | M20: RESERVAS | N20: DIURNO | O20: 6X1 FOLGA DOM/FER | P20: 09H - 07:00-16:00 C/INT SEG- SEX/04H S/D | Q20: CANDIDATA ALYCIA EM PESQUISA 08/05 - CANDIDATA ALYCIA APROVADA 11/05 | R20: INDIQUE UM AMIGO | S20: 11 95585-2637 | T20: BEATRIZ | U20: 46153 | V20: ALYCIA CRISTINA VILELA | W20: ADMITIDO | X20: 46157 | Y20: 46160 | Z20: 145975 | AB20: 0
A21: 29897 | B21: 1 | C21: 46126 | D21: =TODAY()-C21 -> 101 | E21: =IF(W21="ADMITIDO","ADMITIDO",IF(W21="CANCELADA","CANCELADA",IF(H21="","",IF(H21="ADMITIDO","ADMITIDO",IF(H21="CANCELADA","CANCELADA",IF(OR(H21="ANALISE CANCELAMENTO",H21="ANÁLISE CANCELAMENTO"),"EM ANÁLISE",IF(D21="","",IF(D21<=7,"NO PRAZO",IF(D21<=14,"ATENÇÃO","CRÍTICO"))))))))) -> ADMITIDO | F21: SEGURANÇA | G21: ANDREIA | H21: =W21 -> ADMITIDO | I21: =IF(W21="ADMITIDO","ADMITIDO",IF(W21="CANCELADA","CANCELADA",IF(H21="","",IFERROR(_xlfn.XLOOKUP(H21,Listas!I:I,Listas!J:J),"OUTROS")))) -> ADMITIDO | J21: VIGIA | K21: MARCELO RODRIGUES CARUNCHO CARNAVAL | L21: VILLA DAS ARTES | M21: SALTO | N21: DIURNO | O21: 12X36 | P21: 12H - 06:00 - 18:00 C/ 1H INTERV | T21: ANA | U21: 46139 | V21: STEPHANE BEATRIZ DA SILVA | W21: ADMITIDO | X21: 46141 | Y21: 46142 | Z21: 914200 | AB21: 0
A22: 29467 | B22: 1 | C22: 46099 | D22: =TODAY()-C22 -> 128 | E22: =IF(W22="ADMITIDO","ADMITIDO",IF(W22="CANCELADA","CANCELADA",IF(H22="","",IF(H22="ADMITIDO","ADMITIDO",IF(H22="CANCELADA","CANCELADA",IF(OR(H22="ANALISE CANCELAMENTO",H22="ANÁLISE CANCELAMENTO"),"EM ANÁLISE",IF(D22="","",IF(D22<=7,"NO PRAZO",IF(D22<=14,"ATENÇÃO","CRÍTICO"))))))))) -> ADMITIDO | F22: FACILITIES | G22: NATHALYA | H22: =W22 -> ADMITIDO | I22: =IF(W22="ADMITIDO","ADMITIDO",IF(W22="CANCELADA","CANCELADA",IF(H22="","",IFERROR(_xlfn.XLOOKUP(H22,Listas!I:I,Listas!J:J),"OUTROS")))) -> ADMITIDO | J22: AUXILIAR DE LIMPEZA | K22: MAIARA RODRIGUES DE ANDRADE COSTA | L22: SPAZIO BONFIGLIOLI | M22: JUNDIAÍ | N22: DIURNO | O22: 6X1 FOLGA DOM/FER | P22: 09H - 08:00-17:00 C/INT SEG- SEX/04H SAB | Q22: CANDIDATA REGINA APROVADA 20/03 (Parou de responder) - CANDIDATA ELIANA APROVADA 24/03 (Parou de responder) - CANDIDATA LUCIMAR APROVADA 13/04 | R22: WHATSAPP | S22: 11 95244-1563 | T22: RITA | U22: 46125 | V22: LUCIMAR DA SILVA PEREIRA | W22: ADMITIDO | X22: 46132 | Y22: 46134 | Z22: 145849 | AA22: Inicio acordado com a recrutadora | AB22: 0
A23: 29800 | B23: 1 | C23: 46122 | D23: =TODAY()-C23 -> 105 | E23: =IF(W23="ADMITIDO","ADMITIDO",IF(W23="CANCELADA","CANCELADA",IF(H23="","",IF(H23="ADMITIDO","ADMITIDO",IF(H23="CANCELADA","CANCELADA",IF(OR(H23="ANALISE CANCELAMENTO",H23="ANÁLISE CANCELAMENTO"),"EM ANÁLISE",IF(D23="","",IF(D23<=7,"NO PRAZO",IF(D23<=14,"ATENÇÃO","CRÍTICO"))))))))) -> ADMITIDO | F23: FACILITIES | G23: FREITAS | H23: =W23 -> ADMITIDO | I23: =IF(W23="ADMITIDO","ADMITIDO",IF(W23="CANCELADA","CANCELADA",IF(H23="","",IFERROR(_xlfn.XLOOKUP(H23,Listas!I:I,Listas!J:J),"OUTROS")))) -> ADMITIDO | J23: AUXILIAR DE LIMPEZA | K23: KELLY ROBERTA FRATUCCI | L23: ADP BRASIL - MATRIZ SP | M23: SÃO PAULO | N23: DIURNO | O23: 6X1 FOLGA DOM/FER | P23: 08:20H - 13:40 - 22:00 C/ 1H INTERV | T23: ROSI | U23: 46129 | V23: LIGIA CLAUDIA DA SILVA | W23: ADMITIDO | X23: 46135 | Y23: 46136 | Z23: 914148 | AB23: 0
A24: 29472 | B24: 1 | C24: 46100 | D24: =TODAY()-C24 -> 127 | E24: =IF(W24="ADMITIDO","ADMITIDO",IF(W24="CANCELADA","CANCELADA",IF(H24="","",IF(H24="ADMITIDO","ADMITIDO",IF(H24="CANCELADA","CANCELADA",IF(OR(H24="ANALISE CANCELAMENTO",H24="ANÁLISE CANCELAMENTO"),"EM ANÁLISE",IF(D24="","",IF(D24<=7,"NO PRAZO",IF(D24<=14,"ATENÇÃO","CRÍTICO"))))))))) -> CANCELADA | F24: FACILITIES | G24: GIOVANNA | H24: CANCELADA | I24: =IF(W24="ADMITIDO","ADMITIDO",IF(W24="CANCELADA","CANCELADA",IF(H24="","",IFERROR(_xlfn.XLOOKUP(H24,Listas!I:I,Listas!J:J),"OUTROS")))) -> CANCELADA | J24: AUXILIAR DE LIMPEZA | K24: THAIS ALVES DE SOUZA | L24: GRANI AMICI | M24: JUNDIAÍ | N24: DIURNO | O24: 6X1 FOLGA DOM/FER | P24: 09H - 12:00-21:00 C/ INT SEG-SEX/04H SAB | Q24: Vaga Cancelada por Souza via email 20/04 | W24: CANCELADA | AB24: 0
A25: 29490 | B25: 1 | C25: 46101 | D25: =TODAY()-C25 -> 126 | E25: =IF(W25="ADMITIDO","ADMITIDO",IF(W25="CANCELADA","CANCELADA",IF(H25="","",IF(H25="ADMITIDO","ADMITIDO",IF(H25="CANCELADA","CANCELADA",IF(OR(H25="ANALISE CANCELAMENTO",H25="ANÁLISE CANCELAMENTO"),"EM ANÁLISE",IF(D25="","",IF(D25<=7,"NO PRAZO",IF(D25<=14,"ATENÇÃO","CRÍTICO"))))))))) -> ADMITIDO | F25: FACILITIES | G25: NATHALYA | H25: ADMITIDO | I25: =IF(W25="ADMITIDO","ADMITIDO",IF(W25="CANCELADA","CANCELADA",IF(H25="","",IFERROR(_xlfn.XLOOKUP(H25,Listas!I:I,Listas!J:J),"OUTROS")))) -> ADMITIDO | J25: AUXILIAR DE SERVIÇOS GERAIS | K25: MAIARA RODRIGUES DE ANDRADE COSTA | L25: FACILITIES7 - RESERVA TECNICA | M25: JUNDIAÍ | N25: DIURNO | O25: 6X1 FOLGA DOM/FER | P25: 09H - 07:00-16:00 C/INT SEG- SEX/04H SAB | T25: RITA | U25: 46148 | V25: KAYAN VICTOR WESCESLAU MARTINS | W25: ADMITIDO | X25: 46150 | Y25: 46153 | Z25: 145936 | AB25: 0
A26: 29485 | B26: 1 | C26: 46101 | D26: =TODAY()-C26 -> 126 | E26: =IF(W26="ADMITIDO","ADMITIDO",IF(W26="CANCELADA","CANCELADA",IF(H26="","",IF(H26="ADMITIDO","ADMITIDO",IF(H26="CANCELADA","CANCELADA",IF(OR(H26="ANALISE CANCELAMENTO",H26="ANÁLISE CANCELAMENTO"),"EM ANÁLISE",IF(D26="","",IF(D26<=7,"NO PRAZO",IF(D26<=14,"ATENÇÃO","CRÍTICO"))))))))) -> CANCELADA | F26: FACILITIES | G26: ELONY | H26: CANCELADA | I26: =IF(W26="ADMITIDO","ADMITIDO",IF(W26="CANCELADA","CANCELADA",IF(H26="","",IFERROR(_xlfn.XLOOKUP(H26,Listas!I:I,Listas!J:J),"OUTROS")))) -> CANCELADA | J26: LÍDER DE LIMPEZA 13 | K26: ELIANA MARIA MOREIRA BRANSANI | L26: FACULDADE SAO LEOPOLDO MANDIC - MATRIZ | M26: CAMPINAS | N26: NOTURNO | O26: 6X1 FOLGA DOM/FER | P26: 08H - 22:00 - 06:00 C/ 1H INTERV | Q26: Haverá promoção Interna - Supervisora Eliana - 20/04 - aguardar Elony, aporvado o cancelamento Eliana via whats | W26: CANCELADA | AB26: 0
A27: 29480 | B27: 1 | C27: 46101 | D27: =TODAY()-C27 -> 126 | E27: =IF(W27="ADMITIDO","ADMITIDO",IF(W27="CANCELADA","CANCELADA",IF(H27="","",IF(H27="ADMITIDO","ADMITIDO",IF(H27="CANCELADA","CANCELADA",IF(OR(H27="ANALISE CANCELAMENTO",H27="ANÁLISE CANCELAMENTO"),"EM ANÁLISE",IF(D27="","",IF(D27<=7,"NO PRAZO",IF(D27<=14,"ATENÇÃO","CRÍTICO"))))))))) -> CANCELADA | F27: ADM | G27: ANDREIA | H27: CANCELADA | I27: =IF(W27="ADMITIDO","ADMITIDO",IF(W27="CANCELADA","CANCELADA",IF(H27="","",IFERROR(_xlfn.XLOOKUP(H27,Listas!I:I,Listas!J:J),"OUTROS")))) -> CANCELADA | J27: ASSISTENTE OPERACIONAL 3 | K27: MARCOS TOLEDO | L27: PCO - PLANEJAMENTO E CONTROLE OPERACIONAL | M27: ADM | N27: DIURNO | O27: 12X36 | P27: 12H - 06:00 - 18:00 C/ 1H INTERV | W27: CANCELADA | AB27: 0
A28: 29502 | B28: 1 | C28: 46104 | D28: =TODAY()-C28 -> 123 | E28: =IF(W28="ADMITIDO","ADMITIDO",IF(W28="CANCELADA","CANCELADA",IF(H28="","",IF(H28="ADMITIDO","ADMITIDO",IF(H28="CANCELADA","CANCELADA",IF(OR(H28="ANALISE CANCELAMENTO",H28="ANÁLISE CANCELAMENTO"),"EM ANÁLISE",IF(D28="","",IF(D28<=7,"NO PRAZO",IF(D28<=14,"ATENÇÃO","CRÍTICO"))))))))) -> ADMITIDO | F28: VIGILANCIA | G28: GIOVANNA | H28: =W28 -> ADMITIDO | I28: =IF(W28="ADMITIDO","ADMITIDO",IF(W28="CANCELADA","CANCELADA",IF(H28="","",IFERROR(_xlfn.XLOOKUP(H28,Listas!I:I,Listas!J:J),"OUTROS")))) -> ADMITIDO | J28: VIGILANTE | K28: EVALDO ALMEIDA SANTOS | L28: CROWN EMBALAGENS | M28: CABREÚVA | N28: NOTURNO | O28: 12X36 | P28: 12H - 18:00 - 06:00 C/ 1H INTERV | R28: INDICAÇÃO SUP. EVALDO | S28: +55 15 99143-0502 | T28: BEATRIZ | U28: 14/4 | V28: PABLO HENRIQUE PORFIRIO GUSMÃO | W28: ADMITIDO | X28: 46132 | Y28: 46133 | Z28: 83266 | AB28: 0
A29: 29520 | B29: 1 | C29: 46104 | D29: =TODAY()-C29 -> 123 | E29: =IF(W29="ADMITIDO","ADMITIDO",IF(W29="CANCELADA","CANCELADA",IF(H29="","",IF(H29="ADMITIDO","ADMITIDO",IF(H29="CANCELADA","CANCELADA",IF(OR(H29="ANALISE CANCELAMENTO",H29="ANÁLISE CANCELAMENTO"),"EM ANÁLISE",IF(D29="","",IF(D29<=7,"NO PRAZO",IF(D29<=14,"ATENÇÃO","CRÍTICO"))))))))) -> CRÍTICO | F29: FACILITIES | G29: ELONY | H29: EM DOCUMENTAÇÃO 1 | I29: =IF(W29="ADMITIDO","ADMITIDO",IF(W29="CANCELADA","CANCELADA",IF(H29="","",IFERROR(_xlfn.XLOOKUP(H29,Listas!I:I,Listas!J:J),"OUTROS")))) -> DOCUMENTAÇÃO | J29: OPERADOR DE EMPILHADEIRA 8 | K29: ELIANA MARIA MOREIRA BRANSANI | L29: FITESA NAO TECIDOS S/A | M29: COSMÓPOLIS | N29: DIURNO | O29: 3X3 TRABALHA FERIADO | P29: 12H - 06:00 - 18:00 C/ 1H INTERV | Q29: Funcionário aguadando Liberação do Cliente /Enviado email Nejos dia 23/04 cobrando data de inicio | T29: ANA | U29: 46154 | V29: LUCAS HENRIQUE COLASANTO | W29: INTEGRAÇÃO PROGRAMADA | X29: 46160 | Y29: 46161 | Z29: 914295 | AB29: 0
A30: 29699 | B30: 1 | C30: 46114 | D30: =TODAY()-C30 -> 113 | E30: =IF(W30="ADMITIDO","ADMITIDO",IF(W30="CANCELADA","CANCELADA",IF(H30="","",IF(H30="ADMITIDO","ADMITIDO",IF(H30="CANCELADA","CANCELADA",IF(OR(H30="ANALISE CANCELAMENTO",H30="ANÁLISE CANCELAMENTO"),"EM ANÁLISE",IF(D30="","",IF(D30<=7,"NO PRAZO",IF(D30<=14,"ATENÇÃO","CRÍTICO"))))))))) -> ADMITIDO | F30: FACILITIES | G30: FREITAS | H30: =W30 -> ADMITIDO | I30: =IF(W30="ADMITIDO","ADMITIDO",IF(W30="CANCELADA","CANCELADA",IF(H30="","",IFERROR(_xlfn.XLOOKUP(H30,Listas!I:I,Listas!J:J),"OUTROS")))) -> ADMITIDO | J30: AUXILIAR DE SERVIÇOS GERAIS | K30: MARICLEIA CARDOSO SOARES | L30: ITW CHEMICAL | M30: EMBU | N30: DIURNO | O30: 5X2 FOLGA SÁB/DOM/FER | P30: 09:48H - 06:00 - 15:48 C/ 1H INTERV | T30: ROSI | U30: 46135 | V30: JAENIA GRACIELA SANTOS BRITO | W30: ADMITIDO | X30: 46139 | Y30: 46140 | Z30: 145885 | AB30: 0
A31: 29519 | B31: 1 | C31: 46104 | D31: =TODAY()-C31 -> 123 | E31: =IF(W31="ADMITIDO","ADMITIDO",IF(W31="CANCELADA","CANCELADA",IF(H31="","",IF(H31="ADMITIDO","ADMITIDO",IF(H31="CANCELADA","CANCELADA",IF(OR(H31="ANALISE CANCELAMENTO",H31="ANÁLISE CANCELAMENTO"),"EM ANÁLISE",IF(D31="","",IF(D31<=7,"NO PRAZO",IF(D31<=14,"ATENÇÃO","CRÍTICO"))))))))) -> ADMITIDO | F31: FACILITIES | G31: WILLIAM | H31: =W31 -> ADMITIDO | I31: =IF(W31="ADMITIDO","ADMITIDO",IF(W31="CANCELADA","CANCELADA",IF(H31="","",IFERROR(_xlfn.XLOOKUP(H31,Listas!I:I,Listas!J:J),"OUTROS")))) -> ADMITIDO | J31: AUXILIAR DE MANUTENÇÃO 6 | K31: CRISTIANE APARECIDA VIANA DA SILVA | L31: VISTA PARK | M31: JUNDIAÍ | N31: DIURNO | O31: 6X1 FOLGA DOM/FER | P31: 09H - 08:00-17:00 C/INT SEG- SEX/04H SAB | Q31: CANDIDATO NA NATHALIA | S31: 11 99298-7428 | T31: BEATRIZ | U31: 46129 | V31: STIVE CARDOSO DA LUZ | W31: ADMITIDO | X31: 46135 | Y31: 46136 | Z31: 914130 | AB31: 0
A32: 29488 | B32: 1 | C32: 46105 | D32: =TODAY()-C32 -> 122 | E32: =IF(W32="ADMITIDO","ADMITIDO",IF(W32="CANCELADA","CANCELADA",IF(H32="","",IF(H32="ADMITIDO","ADMITIDO",IF(H32="CANCELADA","CANCELADA",IF(OR(H32="ANALISE CANCELAMENTO",H32="ANÁLISE CANCELAMENTO"),"EM ANÁLISE",IF(D32="","",IF(D32<=7,"NO PRAZO",IF(D32<=14,"ATENÇÃO","CRÍTICO"))))))))) -> ADMITIDO | F32: FACILITIES | G32: ELONY | H32: =W32 -> ADMITIDO | I32: =IF(W32="ADMITIDO","ADMITIDO",IF(W32="CANCELADA","CANCELADA",IF(H32="","",IFERROR(_xlfn.XLOOKUP(H32,Listas!I:I,Listas!J:J),"OUTROS")))) -> ADMITIDO | J32: ENCARREGADO DE LIMPEZA 5 | K32: ELIANA MARIA MOREIRA BRANSANI | L32: FACULDADE SAO LEOPOLDO MANDIC - MATRIZ | M32: CAMPINAS | N32: DIURNO | O32: 6X1 FOLGA DOM/FER | P32: 08:20H - 13:40 - 22:00 C/ 1H INTERV | Q32: Indicada pelo cliente | S32: 19 98830 1725 | T32: ANA | U32: 46135 | V32: FATIMA DOS REIS LEÃO | W32: ADMITIDO | X32: 46141 | Y32: 46142 | Z32: 145897 | AB32: 0
A33: 29529 | B33: 1 | C33: 46105 | D33: =TODAY()-C33 -> 122 | E33: =IF(W33="ADMITIDO","ADMITIDO",IF(W33="CANCELADA","CANCELADA",IF(H33="","",IF(H33="ADMITIDO","ADMITIDO",IF(H33="CANCELADA","CANCELADA",IF(OR(H33="ANALISE CANCELAMENTO",H33="ANÁLISE CANCELAMENTO"),"EM ANÁLISE",IF(D33="","",IF(D33<=7,"NO PRAZO",IF(D33<=14,"ATENÇÃO","CRÍTICO"))))))))) -> ADMITIDO | F33: SEGURANÇA | G33: ELONY | H33: =W33 -> ADMITIDO | I33: =IF(W33="ADMITIDO","ADMITIDO",IF(W33="CANCELADA","CANCELADA",IF(H33="","",IFERROR(_xlfn.XLOOKUP(H33,Listas!I:I,Listas!J:J),"OUTROS")))) -> ADMITIDO | J33: VIGIA CONDUTOR | K33: JOSIMAR ALVES DE LIMA | L33: JARDIM DOS LAGOS | M33: INDAIATUBA | N33: NOTURNO | O33: 12X36 | P33: 12H - 18:00 - 06:00 C/ 1H INTERV | S33: 19 99805 1068 | T33: ANA | U33: 46132 | V33: LARISSA CRISTINA DE MELO SANTOS | W33: ADMITIDO | X33: 46148 | Y33: 46149 | Z33: 914229 | AB33: 0
A34: 29521 | B34: 1 | C34: 46105 | D34: =TODAY()-C34 -> 122 | E34: =IF(W34="ADMITIDO","ADMITIDO",IF(W34="CANCELADA","CANCELADA",IF(H34="","",IF(H34="ADMITIDO","ADMITIDO",IF(H34="CANCELADA","CANCELADA",IF(OR(H34="ANALISE CANCELAMENTO",H34="ANÁLISE CANCELAMENTO"),"EM ANÁLISE",IF(D34="","",IF(D34<=7,"NO PRAZO",IF(D34<=14,"ATENÇÃO","CRÍTICO"))))))))) -> ADMITIDO | F34: FACILITIES | G34: FREITAS | H34: ADMITIDO | I34: =IF(W34="ADMITIDO","ADMITIDO",IF(W34="CANCELADA","CANCELADA",IF(H34="","",IFERROR(_xlfn.XLOOKUP(H34,Listas!I:I,Listas!J:J),"OUTROS")))) -> ADMITIDO | J34: AUXILIAR DE LIMPEZA | K34: MARICLEIA CARDOSO SOARES | L34: NEO PARTS | M34: TATUÍ | N34: DIURNO | O34: 6X1 TROCA SAB FOL DOM/FER | P34: 08:20H - 13:40 - 22:00 C/ 1H INTERV | R34: RE 141366 - JACIRA | S34: 15996712142 | T34: PATRICIA | U34: 46134 | V34: CLAUDIA APARECIDA PAES CAMARGO | W34: ADMITIDO | X34: 46146 | Y34: 46146 | Z34: 145910 | AA34: Patricia, atualizar | AB34: 0
A35: 29533 | B35: 1 | C35: 46105 | D35: =TODAY()-C35 -> 122 | E35: =IF(W35="ADMITIDO","ADMITIDO",IF(W35="CANCELADA","CANCELADA",IF(H35="","",IF(H35="ADMITIDO","ADMITIDO",IF(H35="CANCELADA","CANCELADA",IF(OR(H35="ANALISE CANCELAMENTO",H35="ANÁLISE CANCELAMENTO"),"EM ANÁLISE",IF(D35="","",IF(D35<=7,"NO PRAZO",IF(D35<=14,"ATENÇÃO","CRÍTICO"))))))))) -> CRÍTICO | F35: FACILITIES | G35: GIOVANNA | H35: TRIAGEM 3 | I35: =IF(W35="ADMITIDO","ADMITIDO",IF(W35="CANCELADA","CANCELADA",IF(H35="","",IFERROR(_xlfn.XLOOKUP(H35,Listas!I:I,Listas!J:J),"OUTROS")))) -> TRIAGEM | J35: AUXILIAR DE SERVIÇOS GERAIS | K35: MIGUEL GIOSA PIVA | L35: SENSIENT | M35: JUNDIAÍ | N35: DIURNO | O35: 5X2 FOLGA SÁB/DOM/FER | P35: 08H - 14:00 - 22:00 C/ 1 INTERV | Q35: Desistência de candidatos, Reteve JERONIMO SANTOS DE ALMEIDA | AB35: 0
A36: 29554 | B36: 1 | C36: 46106 | D36: =TODAY()-C36 -> 121 | E36: =IF(W36="ADMITIDO","ADMITIDO",IF(W36="CANCELADA","CANCELADA",IF(H36="","",IF(H36="ADMITIDO","ADMITIDO",IF(H36="CANCELADA","CANCELADA",IF(OR(H36="ANALISE CANCELAMENTO",H36="ANÁLISE CANCELAMENTO"),"EM ANÁLISE",IF(D36="","",IF(D36<=7,"NO PRAZO",IF(D36<=14,"ATENÇÃO","CRÍTICO"))))))))) -> ADMITIDO | F36: FACILITIES | G36: FREITAS | H36: ADMITIDO | I36: =IF(W36="ADMITIDO","ADMITIDO",IF(W36="CANCELADA","CANCELADA",IF(H36="","",IFERROR(_xlfn.XLOOKUP(H36,Listas!I:I,Listas!J:J),"OUTROS")))) -> ADMITIDO | J36: AUXILIAR DE LIMPEZA | K36: KELLY ROBERTA FRATUCCI | L36: URBAN LIVING PACAEMBU | M36: SÃO PAULO | N36: DIURNO | O36: 6X1 TROCA SÁB/DOM | P36: 08:20H - 11:00 - 19:20 C/ 1H INTERV | Q36: Candidato Jose Luiz declinou da vaga dia 17/04 | S36: 11971655331 | T36: ROSI | U36: 46135 | V36: ELITON JAIRMILE DOS SANTOS | W36: ADMITIDO | X36: 46117 | Y36: 46117 | AB36: 0
A37: 29546 | B37: 1 | C37: 46106 | D37: =TODAY()-C37 -> 121 | E37: =IF(W37="ADMITIDO","ADMITIDO",IF(W37="CANCELADA","CANCELADA",IF(H37="","",IF(H37="ADMITIDO","ADMITIDO",IF(H37="CANCELADA","CANCELADA",IF(OR(H37="ANALISE CANCELAMENTO",H37="ANÁLISE CANCELAMENTO"),"EM ANÁLISE",IF(D37="","",IF(D37<=7,"NO PRAZO",IF(D37<=14,"ATENÇÃO","CRÍTICO"))))))))) -> ADMITIDO | F37: FACILITIES | G37: WILLIAM | H37: ADMITIDO | I37: =IF(W37="ADMITIDO","ADMITIDO",IF(W37="CANCELADA","CANCELADA",IF(H37="","",IFERROR(_xlfn.XLOOKUP(H37,Listas!I:I,Listas!J:J),"OUTROS")))) -> ADMITIDO | J37: AUXILIAR DE LIMPEZA | K37: CRISTIANE APARECIDA VIANA DA SILVA | L37: VISTA PARK | M37: JUNDIAÍ | N37: DIURNO | O37: 6X1 TROCA SÁB/DOM FOLGA FER | P37: 09H - 08:00-17:00 C/INT - 12H-16H S/D | Q37: CANDIDATA GINEUSA APROVADA | R37: RECEPTIVO NO WHATSAPP | T37: PATRICIA | U37: 14/04 | V37: GINEUSA SILVA | W37: ADMITIDO | X37: 46132 | Y37: 46134 | Z37: 914152 | AB37: 0
A38: 29564 | B38: 1 | C38: 46107 | D38: =TODAY()-C38 -> 120 | E38: =IF(W38="ADMITIDO","ADMITIDO",IF(W38="CANCELADA","CANCELADA",IF(H38="","",IF(H38="ADMITIDO","ADMITIDO",IF(H38="CANCELADA","CANCELADA",IF(OR(H38="ANALISE CANCELAMENTO",H38="ANÁLISE CANCELAMENTO"),"EM ANÁLISE",IF(D38="","",IF(D38<=7,"NO PRAZO",IF(D38<=14,"ATENÇÃO","CRÍTICO"))))))))) -> ADMITIDO | F38: FACILITIES | G38: ELONY | H38: ADMITIDO | I38: =IF(W38="ADMITIDO","ADMITIDO",IF(W38="CANCELADA","CANCELADA",IF(H38="","",IFERROR(_xlfn.XLOOKUP(H38,Listas!I:I,Listas!J:J),"OUTROS")))) -> ADMITIDO | J38: AUXILIAR DE LIMPEZA 23 | K38: GISLENE BESSA DOS SANTOS LOPES | L38: CAEP | M38: CAMPINAS | N38: DIURNO | O38: 6X1 FOLGA SEXTA | P38: 08:20H - 06:00 - 14:20 C/ 1H INTERV* | T38: ANA | U38: 46146 | V38: YELEZITA MARIA | W38: ADMITIDO | X38: 46155 | Y38: 46156 | Z38: 145944 | AA38: Indicação de supervisão - aguardou termono do aviso | AB38: 0
A39: 29581 | B39: 1 | C39: 46107 | D39: =TODAY()-C39 -> 120 | E39: =IF(W39="ADMITIDO","ADMITIDO",IF(W39="CANCELADA","CANCELADA",IF(H39="","",IF(H39="ADMITIDO","ADMITIDO",IF(H39="CANCELADA","CANCELADA",IF(OR(H39="ANALISE CANCELAMENTO",H39="ANÁLISE CANCELAMENTO"),"EM ANÁLISE",IF(D39="","",IF(D39<=7,"NO PRAZO",IF(D39<=14,"ATENÇÃO","CRÍTICO"))))))))) -> CRÍTICO | F39: FACILITIES | G39: ELONY | H39: TRIAGEM 1 | I39: =IF(W39="ADMITIDO","ADMITIDO",IF(W39="CANCELADA","CANCELADA",IF(H39="","",IFERROR(_xlfn.XLOOKUP(H39,Listas!I:I,Listas!J:J),"OUTROS")))) -> TRIAGEM | J39: AUXILIAR DE LIMPEZA | K39: ELIANA MARIA MOREIRA BRANSANI | L39: CAMPINAS5 - FERISTA - FACILITIES | M39: RESERVAS | N39: DIURNO | O39: 5X2 FOLGA SÁB/DOM/FER | P39: 09:48H - 07:00 - 16:48 C/ 1H INTERV | Q39: Vaga de ferista regisão de Indaiatuba | AA39: Candidata - BRUNA CUSTÓDIA DE SOUSA NEVES desistiu no dia 17/04 | AB39: 0
A40: 29572 | B40: 1 | C40: 46107 | D40: =TODAY()-C40 -> 120 | E40: =IF(W40="ADMITIDO","ADMITIDO",IF(W40="CANCELADA","CANCELADA",IF(H40="","",IF(H40="ADMITIDO","ADMITIDO",IF(H40="CANCELADA","CANCELADA",IF(OR(H40="ANALISE CANCELAMENTO",H40="ANÁLISE CANCELAMENTO"),"EM ANÁLISE",IF(D40="","",IF(D40<=7,"NO PRAZO",IF(D40<=14,"ATENÇÃO","CRÍTICO"))))))))) -> CANCELADA | F40: FACILITIES | G40: GIOVANNA | H40: CANCELADA | I40: =IF(W40="ADMITIDO","ADMITIDO",IF(W40="CANCELADA","CANCELADA",IF(H40="","",IFERROR(_xlfn.XLOOKUP(H40,Listas!I:I,Listas!J:J),"OUTROS")))) -> CANCELADA | J40: AUXILIAR DE LIMPEZA | K40: MIGUEL GIOSA PIVA | L40: MORADA DA SERRA | M40: JUNDIAÍ | N40: DIURNO | O40: 6X1 TROCA SÁB/DOM FOLGA FER | P40: 09H - 08:00-17:00 C/INT SEG- SEX/04H SD | Q40: Remanejamento interno | W40: CANCELADA | AB40: 0
...

Sheet Planilha  de Vagas R&S
A1: COD | B1: VAGAS | C1: DATA DE ABERTURA DA VAGA | D1: DIAS ABERTA | E1: CRITICIDADE | F1: SERVIÇO | G1: RECRUTADOR | H1: STATUS RECRUTADOR | I1: STATUS | J1: CARGO | K1: SUPERVISÃO | L1: CLIENTE | N1: LOCALIDADE | O1: TURNO | P1: ESCALA | Q1: JORNADA | R1: COMENTÁRIOS RECRUTADOR | S1: FONTE DE CAPTAÇÃO | T1: TELEFONE | U1: RESPONSÁVEL | V1: DATA DE RECEBIMENTO | W1: NOME DO CANDIDATO | X1: STATUS DOCUMENTAÇÃO | Y1: INTEGRAÇÃO | Z1: ADMISSÃO | AA1: RE | AB1: COMENTÁRIOS E OBSERVAÇÕES | AC1: DATA DO CANCELAMENTO DA VAGA | AD1: DESISTÊNCIAS
A2: 28789 | B2: 1 | C2: 46048 | D2: =TODAY()-C2 -> 179 | E2: =IF(X2="ADMITIDO","ADMITIDO",IF(X2="CANCELADA","CANCELADA",IF(H2="","",IF(H2="ADMITIDO","ADMITIDO",IF(H2="CANCELADA","CANCELADA",IF(OR(H2="ANALISE CANCELAMENTO",H2="ANÁLISE CANCELAMENTO"),"EM ANÁLISE",IF(D2="","",IF(D2<=7,"NO PRAZO",IF(D2<=14,"ATENÇÃO","CRÍTICO"))))))))) -> ADMITIDO | F2: SEGURANÇA | G2: ELONY | H2: =X2 -> ADMITIDO | I2: =IF(X2="ADMITIDO","ADMITIDO",IF(X2="CANCELADA","CANCELADA",IF(H2="","",IFERROR(_xlfn.XLOOKUP(H2,Listas!I:I,Listas!J:J),"OUTROS")))) -> ADMITIDO | J2: VIGIA 6 | K2: MARCELO RODRIGUES CARUNCHO CARNAVAL | L2: CAMPINAS3 - RESERVA TECNICA - SEGURANCA | N2: RESERVAS | O2: DIURNO | P2: 12X36 | Q2: 12H - 06:00 - 18:00 C/ 1H INTERV | R2: Vaga da Bruna / Houveram 2 desistências - passada Elony dia 20/04 | U2: ANA | V2: 46142 | W2: WAGNER BENEDITO DA SILVA | X2: ADMITIDO | Y2: 46150 | Z2: 46151 | AA2: 914242 | AB2: Candidato - JULIO CEZAR DE OLIVEIRA CAMISA desistiu no dia 28/04 | AD2: 0
A3: 28991 | B3: 1 | C3: 46063 | D3: =TODAY()-C3 -> 164 | E3: =IF(X3="ADMITIDO","ADMITIDO",IF(X3="CANCELADA","CANCELADA",IF(H3="","",IF(H3="ADMITIDO","ADMITIDO",IF(H3="CANCELADA","CANCELADA",IF(OR(H3="ANALISE CANCELAMENTO",H3="ANÁLISE CANCELAMENTO"),"EM ANÁLISE",IF(D3="","",IF(D3<=7,"NO PRAZO",IF(D3<=14,"ATENÇÃO","CRÍTICO"))))))))) -> ADMITIDO | F3: FACILITIES | G3: FREITAS | H3: =X3 -> ADMITIDO | I3: =IF(X3="ADMITIDO","ADMITIDO",IF(X3="CANCELADA","CANCELADA",IF(H3="","",IFERROR(_xlfn.XLOOKUP(H3,Listas!I:I,Listas!J:J),"OUTROS")))) -> ADMITIDO | J3: AUXILIAR DE SERVIÇOS GERAIS | K3: KELLY ROBERTA FRATUCCI | L3: PROMAX BARDAHL | N3: CAJAMAR | O3: DIURNO | P3: 5X2 FOLGA SÁB/DOM/FER | Q3: 09:48H - 06:00 - 15:48 C/ 1H INTERV | U3: ROSI | V3: 46126 | W3: Paulo Henrique | X3: ADMITIDO | Y3: 46134 | Z3: 46135 | AA3: 914145 | AD3: 0
A4: 29028 | B4: 1 | C4: 46065 | D4: =TODAY()-C4 -> 162 | E4: =IF(X4="ADMITIDO","ADMITIDO",IF(X4="CANCELADA","CANCELADA",IF(H4="","",IF(H4="ADMITIDO","ADMITIDO",IF(H4="CANCELADA","CANCELADA",IF(OR(H4="ANALISE CANCELAMENTO",H4="ANÁLISE CANCELAMENTO"),"EM ANÁLISE",IF(D4="","",IF(D4<=7,"NO PRAZO",IF(D4<=14,"ATENÇÃO","CRÍTICO"))))))))) -> CANCELADA | F4: FACILITIES | G4: ELONY | H4: CANCELADA | I4: =IF(X4="ADMITIDO","ADMITIDO",IF(X4="CANCELADA","CANCELADA",IF(H4="","",IFERROR(_xlfn.XLOOKUP(H4,Listas!I:I,Listas!J:J),"OUTROS")))) -> CANCELADA | J4: AUXILIAR DE LIMPEZA | K4: ELIANA MARIA MOREIRA BRANSANI | L4: CAMPINAS5 - RESERVA TECNICA - FACILITIES | N4: RESERVAS | O4: NOTURNO | P4: 6X1 FOLGA DOM/FER | Q4: 08:20H - 22:00 - 06:20 C/ 1H INTERV | R4: Enviado email 20/04 - Eliana para confirmar cancelamento, confirmado cancelamento email 22/04 | X4: CANCELADA | AD4: 0
A5: 29493 | B5: 1 | C5: 46104 | D5: =TODAY()-C5 -> 123 | E5: =IF(X5="ADMITIDO","ADMITIDO",IF(X5="CANCELADA","CANCELADA",IF(H5="","",IF(H5="ADMITIDO","ADMITIDO",IF(H5="CANCELADA","CANCELADA",IF(OR(H5="ANALISE CANCELAMENTO",H5="ANÁLISE CANCELAMENTO"),"EM ANÁLISE",IF(D5="","",IF(D5<=7,"NO PRAZO",IF(D5<=14,"ATENÇÃO","CRÍTICO"))))))))) -> ADMITIDO | F5: FACILITIES | G5: NATHALYA | H5: ADMITIDO | I5: =IF(X5="ADMITIDO","ADMITIDO",IF(X5="CANCELADA","CANCELADA",IF(H5="","",IFERROR(_xlfn.XLOOKUP(H5,Listas!I:I,Listas!J:J),"OUTROS")))) -> ADMITIDO | J5: AUXILIAR DE LIMPEZA | K5: MAIARA RODRIGUES DE ANDRADE COSTA | L5: THE ONE OFFICE | N5: JUNDIAÍ | O5: DIURNO | P5: 6X1 FOLGA DOM/FER | Q5: 09H - 12:00-21:00 C/ INT SEG-SEX/04H SAB | S5: WHATSAPP | T5: 11 97375-0776 | U5: PATRICIA | V5: 46134 | W5: RAISSA APARECIDA JESUS | X5: ADMITIDO | Y5: 46146 | Z5: 46147 | AA5: 145905 | AD5: 0
A6: 29199 | B6: 1 | C6: 46080 | D6: =TODAY()-C6 -> 147 | E6: =IF(X6="ADMITIDO","ADMITIDO",IF(X6="CANCELADA","CANCELADA",IF(H6="","",IF(H6="ADMITIDO","ADMITIDO",IF(H6="CANCELADA","CANCELADA",IF(OR(H6="ANALISE CANCELAMENTO",H6="ANÁLISE CANCELAMENTO"),"EM ANÁLISE",IF(D6="","",IF(D6<=7,"NO PRAZO",IF(D6<=14,"ATENÇÃO","CRÍTICO"))))))))) -> ADMITIDO | F6: FACILITIES | G6: GIOVANNA | H6: ADMITIDO | I6: =IF(X6="ADMITIDO","ADMITIDO",IF(X6="CANCELADA","CANCELADA",IF(H6="","",IFERROR(_xlfn.XLOOKUP(H6,Listas!I:I,Listas!J:J),"OUTROS")))) -> ADMITIDO | J6: AUXILIAR DE LIMPEZA | K6: MIGUEL GIOSA PIVA | L6: FACILITIES2 - RESERVA TECNICA | N6: RESERVAS | O6: DIURNO | P6: 6X1 TROCA SÁB/DOM FOLGA FER | Q6: 09H - 07:00-16:00 C/INT SEG- SEX/04H S/D | S6: WHATSAPP | T6: +55 11 95146-6912 | U6: PATRICIA | V6: 46134 | W6: SARA PASSOS GARCIA | X6: ADMITIDO | Y6: 46146 | Z6: 46147 | AA6: 145909 | AD6: 0
B7: 1 | C7: 46080 | D7: =TODAY()-C7 -> 147 | E7: =IF(X7="ADMITIDO","ADMITIDO",IF(X7="CANCELADA","CANCELADA",IF(H7="","",IF(H7="ADMITIDO","ADMITIDO",IF(H7="CANCELADA","CANCELADA",IF(OR(H7="ANALISE CANCELAMENTO",H7="ANÁLISE CANCELAMENTO"),"EM ANÁLISE",IF(D7="","",IF(D7<=7,"NO PRAZO",IF(D7<=14,"ATENÇÃO","CRÍTICO"))))))))) -> ADMITIDO | F7: FACILITIES | G7: GIOVANNA | H7: ADMITIDO | I7: =IF(X7="ADMITIDO","ADMITIDO",IF(X7="CANCELADA","CANCELADA",IF(H7="","",IFERROR(_xlfn.XLOOKUP(H7,Listas!I:I,Listas!J:J),"OUTROS")))) -> ADMITIDO | J7: AUXILIAR DE LIMPEZA | K7: MIGUEL GIOSA PIVA | L7: FACILITIES2 - RESERVA TECNICA | N7: RESERVAS | O7: DIURNO | P7: 6X1 TROCA SÁB/DOM FOLGA FER | Q7: 09H - 07:00-16:00 C/INT SEG- SEX/04H S/D | S7: WHATSAPP | U7: RITA | V7: 46141 | W7: PATRICIA APARECIDA DE CARVALHO | X7: ADMITIDO | Y7: 46147 | Z7: 46148 | AA7: 145918 | AD7: 0
A8: 29200 | B8: 1 | C8: 46080 | D8: =TODAY()-C8 -> 147 | E8: =IF(X8="ADMITIDO","ADMITIDO",IF(X8="CANCELADA","CANCELADA",IF(H8="","",IF(H8="ADMITIDO","ADMITIDO",IF(H8="CANCELADA","CANCELADA",IF(OR(H8="ANALISE CANCELAMENTO",H8="ANÁLISE CANCELAMENTO"),"EM ANÁLISE",IF(D8="","",IF(D8<=7,"NO PRAZO",IF(D8<=14,"ATENÇÃO","CRÍTICO"))))))))) -> ADMITIDO | F8: FACILITIES | G8: GIOVANNA | H8: ADMITIDO | I8: =IF(X8="ADMITIDO","ADMITIDO",IF(X8="CANCELADA","CANCELADA",IF(H8="","",IFERROR(_xlfn.XLOOKUP(H8,Listas!I:I,Listas!J:J),"OUTROS")))) -> ADMITIDO | J8: AUXILIAR DE LIMPEZA | K8: MIGUEL GIOSA PIVA | L8: MAESTRAL COML. | N8: JUNDIAÍ | O8: DIURNO | P8: 5X2 FOLGA SÁB/DOM/FER | Q8: 09:48H - 08:00 - 17:48 C/ 1H INTERV | R8: Desistência de candidatos | S8: PAT JUNDIAI | T8: 11 97390-5487 | U8: PATRICIA | V8: 46149 | W8: MARCOS ALBERTO FERNANDES | X8: ADMITIDO | Y8: 46154 | Z8: 46156 | AA8: 145950 | AB8: JOSÉ LUEDSON VIEIRA DA SILVA - Integração foi agendada mas não compareceu e não retornou | AD8: 0
A9: 29288 | B9: 1 | C9: 46086 | D9: =TODAY()-C9 -> 141 | E9: =IF(X9="ADMITIDO","ADMITIDO",IF(X9="CANCELADA","CANCELADA",IF(H9="","",IF(H9="ADMITIDO","ADMITIDO",IF(H9="CANCELADA","CANCELADA",IF(OR(H9="ANALISE CANCELAMENTO",H9="ANÁLISE CANCELAMENTO"),"EM ANÁLISE",IF(D9="","",IF(D9<=7,"NO PRAZO",IF(D9<=14,"ATENÇÃO","CRÍTICO"))))))))) -> ADMITIDO | F9: SEGURANÇA | G9: ELONY | H9: =X9 -> ADMITIDO | I9: =IF(X9="ADMITIDO","ADMITIDO",IF(X9="CANCELADA","CANCELADA",IF(H9="","",IFERROR(_xlfn.XLOOKUP(H9,Listas!I:I,Listas!J:J),"OUTROS")))) -> ADMITIDO | J9: VIGIA 22 | K9: THAIS FERNANDA TOZZI | L9: CANON MEDICAL SYSTEMS DO BRASIL LTDA - CAMPINAS | N9: CAMPINAS | O9: DIURNO | P9: 5X2 FOLGA SÁB/DOM/FER | Q9: 10H - 09:00 - 18:00 C/ 1H INTERV | U9: ANA | V9: 46127 | W9: ANA PAULA GONÇALVES TIGRE | X9: ADMITIDO | Y9: 46139 | Z9: 46130 | AA9: 914174 | AD9: 0
A10: 29258 | B10: 1 | C10: 46086 | D10: =TODAY()-C10 -> 141 | E10: =IF(X10="ADMITIDO","ADMITIDO",IF(X10="CANCELADA","CANCELADA",IF(H10="","",IF(H10="ADMITIDO","ADMITIDO",IF(H10="CANCELADA","CANCELADA",IF(OR(H10="ANALISE CANCELAMENTO",H10="ANÁLISE CANCELAMENTO"),"EM ANÁLISE",IF(D10="","",IF(D10<=7,"NO PRAZO",IF(D10<=14,"ATENÇÃO","CRÍTICO"))))))))) -> ADMITIDO | F10: FACILITIES | G10: ELONY | H10: =X10 -> ADMITIDO | I10: =IF(X10="ADMITIDO","ADMITIDO",IF(X10="CANCELADA","CANCELADA",IF(H10="","",IFERROR(_xlfn.XLOOKUP(H10,Listas!I:I,Listas!J:J),"OUTROS")))) -> ADMITIDO | J10: AUXILIAR DE LIMPEZA | K10: ELIANA MARIA MOREIRA BRANSANI | L10: NEO RODAS - VINHEDO | N10: VINHEDO | O10: DIURNO | P10: 6X1 FOLGA DOM/FER | Q10: 08:20H - 13:40 - 22:00 C/ 1H INTERV | T10: 19 92006 0596 | U10: ANA | V10: 46160 | W10: JOÃO BATISTA NOVAIS PINTO | X10: ADMITIDO | Y10: 46164 | Z10: 46165 | AA10: 914325 | AD10: 0
A11: 29270 | B11: 1 | C11: 46086 | D11: =TODAY()-C11 -> 141 | E11: =IF(X11="ADMITIDO","ADMITIDO",IF(X11="CANCELADA","CANCELADA",IF(H11="","",IF(H11="ADMITIDO","ADMITIDO",IF(H11="CANCELADA","CANCELADA",IF(OR(H11="ANALISE CANCELAMENTO",H11="ANÁLISE CANCELAMENTO"),"EM ANÁLISE",IF(D11="","",IF(D11<=7,"NO PRAZO",IF(D11<=14,"ATENÇÃO","CRÍTICO"))))))))) -> ADMITIDO | F11: FACILITIES | G11: FREITAS | H11: ADMITIDO | I11: =IF(X11="ADMITIDO","ADMITIDO",IF(X11="CANCELADA","CANCELADA",IF(H11="","",IFERROR(_xlfn.XLOOKUP(H11,Listas!I:I,Listas!J:J),"OUTROS")))) -> ADMITIDO | J11: AUXILIAR DE SERVIÇOS GERAIS | K11: KELLY ROBERTA FRATUCCI | L11: URBAN PACAEMBU | N11: SÃO PAULO | O11: DIURNO | P11: 6X1 FOLGA DOM/FER | Q11: 09H - 07:00-16:00 C/INT SEG- SEX/04H SAB | R11: 27/04 - Cristian não compareceu na integração por 2x | T11: 11960178856 | U11: ROSI | V11: 46140 | W11: RICHARD THIAGO ARNAIS DA SILVA | X11: ADMITIDO | Y11: 46148 | Z11: 46148 | AA11: 914215 | AB11: Vai comparecer amanhã (07/05) | AD11: 0
A12: 29345 | B12: 1 | C12: 46091 | D12: =TODAY()-C12 -> 136 | E12: =IF(X12="ADMITIDO","ADMITIDO",IF(X12="CANCELADA","CANCELADA",IF(H12="","",IF(H12="ADMITIDO","ADMITIDO",IF(H12="CANCELADA","CANCELADA",IF(OR(H12="ANALISE CANCELAMENTO",H12="ANÁLISE CANCELAMENTO"),"EM ANÁLISE",IF(D12="","",IF(D12<=7,"NO PRAZO",IF(D12<=14,"ATENÇÃO","CRÍTICO"))))))))) -> ADMITIDO | F12: FACILITIES | G12: WILLIAM | H12: =X12 -> ADMITIDO | I12: =IF(X12="ADMITIDO","ADMITIDO",IF(X12="CANCELADA","CANCELADA",IF(H12="","",IFERROR(_xlfn.XLOOKUP(H12,Listas!I:I,Listas!J:J),"OUTROS")))) -> ADMITIDO | J12: AUXILIAR DE LIMPEZA | K12: CRISTIANE APARECIDA VIANA DA SILVA | L12: FACILITIES3 - RESERVA TECNICA | N12: RESERVAS | O12: DIURNO | P12: 6X1 FOLGA DOM/FER | Q12: 08:00H - 14:00 - 22:00 C/ 1H INTERV | R12: Cand Jhoni desistiu/ Cbadidata Maria desistiu/ cand. Reginaldo em documentação, desisitiu dia 08/05| Pedro aprovado 11/05| | S12: RECEPTIVO NO WHATSAPP | T12: 11 94385-3802 | U12: LUANA | V12: 46153 | W12: PEDRO AUGUSTO DA SILVA COSTA | X12: ADMITIDO | Y12: 46154 | Z12: 46155 | AA12: 145951 | AB12: MARIA APARECIDA MENDES DE SOUZA Exame agendado para o dia 29/04, porém ela não compareceu. Solicitou reagendamento e também não compareceu. Tentativas de contato sem sucesso. REGINALDO RODRIGUES DE LIMA Recebido dia 06/05 declinou por não quer mais a vaga dia 08/05, não realizou ASO | AD12: 0
A13: 29385 | B13: 1 | C13: 46093 | D13: =TODAY()-C13 -> 134 | E13: =IF(X13="ADMITIDO","ADMITIDO",IF(X13="CANCELADA","CANCELADA",IF(H13="","",IF(H13="ADMITIDO","ADMITIDO",IF(H13="CANCELADA","CANCELADA",IF(OR(H13="ANALISE CANCELAMENTO",H13="ANÁLISE CANCELAMENTO"),"EM ANÁLISE",IF(D13="","",IF(D13<=7,"NO PRAZO",IF(D13<=14,"ATENÇÃO","CRÍTICO"))))))))) -> CANCELADA | F13: FACILITIES | G13: NATHALYA | H13: CANCELADA | I13: =IF(X13="ADMITIDO","ADMITIDO",IF(X13="CANCELADA","CANCELADA",IF(H13="","",IFERROR(_xlfn.XLOOKUP(H13,Listas!I:I,Listas!J:J),"OUTROS")))) -> CANCELADA | J13: AUXILIAR DE LIMPEZA | K13: MAIARA RODRIGUES DE ANDRADE COSTA | L13: PASARGADA | N13: JUNDIAÍ | O13: DIURNO | P13: 6X1 TROCA SÁB/DOM FOLGA FER | Q13: 09H -07:00-16:00 C/INT SEG- SEX/04H S/D. | R13: CANDIDATA SIMONE APROVADA 30/03 (Desistiu da vaga) - CANDIDATA LUCIANA APROVADA 09/04 (Declinada por falta de documentos) CNAD MARIANA DO WILLIAM 29/04 | X13: CANCELADA | AB13: MARIANA GOMES: Declinou 30/04 | AD13: 0
A14: 29310 | B14: 1 | C14: 46093 | D14: =TODAY()-C14 -> 134 | E14: =IF(X14="ADMITIDO","ADMITIDO",IF(X14="CANCELADA","CANCELADA",IF(H14="","",IF(H14="ADMITIDO","ADMITIDO",IF(H14="CANCELADA","CANCELADA",IF(OR(H14="ANALISE CANCELAMENTO",H14="ANÁLISE CANCELAMENTO"),"EM ANÁLISE",IF(D14="","",IF(D14<=7,"NO PRAZO",IF(D14<=14,"ATENÇÃO","CRÍTICO"))))))))) -> ADMITIDO | F14: FACILITIES | G14: NATHALYA | H14: =X14 -> ADMITIDO | I14: =IF(X14="ADMITIDO","ADMITIDO",IF(X14="CANCELADA","CANCELADA",IF(H14="","",IFERROR(_xlfn.XLOOKUP(H14,Listas!I:I,Listas!J:J),"OUTROS")))) -> ADMITIDO | J14: bi | K14: LINDBERG TUMOLO | L14: VOLANTES - SERVICO EXTRA | N14: ADM | O14: DIURNO | P14: 5X2 FOLGA SÁB/DOM/FER | Q14: 09:48H - 07:00 - 16:48 C/ 1H INTERV | R14: CANDIDATO CLEBEERTON APROVADO 08/04 (Declinado por ser ex-funcionário, não informou durante a entrevista e não foi autorizado seu retorno) - CANDIDATO CHRISTOFER APROVADO 16/04 | S14: WHATSAPP | T14: 11 93280-6857 | U14: RITA | V14: 46128 | W14: CHRISTOFER BARBOSA ROCHA | X14: ADMITIDO | Y14: 46132 | Z14: 46135 | AA14: 914147 | AB14: Problema com documentos | AD14: 0
A15: 29310 | B15: 1 | C15: 46093 | D15: =TODAY()-C15 -> 134 | E15: =IF(X15="ADMITIDO","ADMITIDO",IF(X15="CANCELADA","CANCELADA",IF(H15="","",IF(H15="ADMITIDO","ADMITIDO",IF(H15="CANCELADA","CANCELADA",IF(OR(H15="ANALISE CANCELAMENTO",H15="ANÁLISE CANCELAMENTO"),"EM ANÁLISE",IF(D15="","",IF(D15<=7,"NO PRAZO",IF(D15<=14,"ATENÇÃO","CRÍTICO"))))))))) -> ADMITIDO | F15: FACILITIES | G15: NATHALYA | H15: =X15 -> ADMITIDO | I15: =IF(X15="ADMITIDO","ADMITIDO",IF(X15="CANCELADA","CANCELADA",IF(H15="","",IFERROR(_xlfn.XLOOKUP(H15,Listas!I:I,Listas!J:J),"OUTROS")))) -> ADMITIDO | J15: JARDINEIRO 2 | K15: LINDBERG TUMOLO | L15: VOLANTES - SERVICO EXTRA | N15: ADM | O15: DIURNO | P15: 5X2 FOLGA SÁB/DOM/FER | Q15: 09:48H - 07:00 - 16:48 C/ 1H INTERV | S15: WHATSAPP | T15: 11 92173-6036 | U15: RITA | V15: 46135 | W15: CLEBERTON APARECIDO | X15: ADMITIDO | Y15: 46140 | Z15: 46141 | AA15: 914178 | AB15: INTEGRAÇÃO DO DIA 27/04 FOI REMANEJADA A PEDIDO DO CANDIDATO PARA O DIA 28/04 | AD15: 0
A16: 29420 | B16: 1 | C16: 46097 | D16: =TODAY()-C16 -> 130 | E16: =IF(X16="ADMITIDO","ADMITIDO",IF(X16="CANCELADA","CANCELADA",IF(H16="","",IF(H16="ADMITIDO","ADMITIDO",IF(H16="CANCELADA","CANCELADA",IF(OR(H16="ANALISE CANCELAMENTO",H16="ANÁLISE CANCELAMENTO"),"EM ANÁLISE",IF(D16="","",IF(D16<=7,"NO PRAZO",IF(D16<=14,"ATENÇÃO","CRÍTICO"))))))))) -> CANCELADA | F16: FACILITIES | G16: GIOVANNA | H16: CANCELADA | I16: =IF(X16="ADMITIDO","ADMITIDO",IF(X16="CANCELADA","CANCELADA",IF(H16="","",IFERROR(_xlfn.XLOOKUP(H16,Listas!I:I,Listas!J:J),"OUTROS")))) -> CANCELADA | J16: AUXILIAR DE SERVIÇOS GERAIS | K16: MIGUEL GIOSA PIVA | L16: CAMINHOS DA SERRA 3 | N16: JUNDIAÍ | O16: DIURNO | P16: 6X1 FOLGA DOM/FER | Q16: 09H - 07:00-16:00 C/INT SEG- SEX/04H SAB | R16: A colaboradora VÂNIA foi remanejada para outro contrato | X16: CANCELADA | AD16: 0
A17: 29417 | B17: 1 | C17: 46097 | D17: =TODAY()-C17 -> 130 | E17: =IF(X17="ADMITIDO","ADMITIDO",IF(X17="CANCELADA","CANCELADA",IF(H17="","",IF(H17="ADMITIDO","ADMITIDO",IF(H17="CANCELADA","CANCELADA",IF(OR(H17="ANALISE CANCELAMENTO",H17="ANÁLISE CANCELAMENTO"),"EM ANÁLISE",IF(D17="","",IF(D17<=7,"NO PRAZO",IF(D17<=14,"ATENÇÃO","CRÍTICO"))))))))) -> ADMITIDO | F17: FACILITIES | G17: GIOVANNA | H17: ADMITIDO | I17: =IF(X17="ADMITIDO","ADMITIDO",IF(X17="CANCELADA","CANCELADA",IF(H17="","",IFERROR(_xlfn.XLOOKUP(H17,Listas!I:I,Listas!J:J),"OUTROS")))) -> ADMITIDO | J17: AUXILIAR DE LIMPEZA | K17: MIGUEL GIOSA PIVA | L17: HORIBA | N17: JUNDIAÍ | O17: DIURNO | P17: 5X2 FOLGA SÁB/DOM/FER | Q17: 09:48H - 07:00 - 16:48 C/ INTERV | S17: WHATSAPP | U17: BEATRIZ | V17: 46150 | W17: ANDREIA DO CARMO DE JESUS | X17: ADMITIDO | Y17: 46156 | Z17: 46160 | AA17: 914285 | AB17: Candidata Claudinéia declinou da vaga em 28/04 - vaga reabera / LUCIANA FERREIRA: Declinamos por falta de retorno 04.05 | AD17: 0
A18: 29444 | B18: 1 | C18: 46098 | D18: =TODAY()-C18 -> 129 | E18: =IF(X18="ADMITIDO","ADMITIDO",IF(X18="CANCELADA","CANCELADA",IF(H18="","",IF(H18="ADMITIDO","ADMITIDO",IF(H18="CANCELADA","CANCELADA",IF(OR(H18="ANALISE CANCELAMENTO",H18="ANÁLISE CANCELAMENTO"),"EM ANÁLISE",IF(D18="","",IF(D18<=7,"NO PRAZO",IF(D18<=14,"ATENÇÃO","CRÍTICO"))))))))) -> ADMITIDO | F18: FACILITIES | G18: WILLIAM | H18: =X18 -> ADMITIDO | I18: =IF(X18="ADMITIDO","ADMITIDO",IF(X18="CANCELADA","CANCELADA",IF(H18="","",IFERROR(_xlfn.XLOOKUP(H18,Listas!I:I,Listas!J:J),"OUTROS")))) -> ADMITIDO | J18: AUXILIAR DE SERVIÇOS GERAIS | K18: CRISTIANE APARECIDA VIANA DA SILVA | L18: FACILITIES3 - RESERVA TECNICA | N18: RESERVAS | O18: DIURNO | P18: 6X1 FOLGA DOM/FER | Q18: 09H - 07:00-16:00 C/INT SEG- SEX/04H SAB | R18: CANDIDATA MARIA APARECIDA APROVADA DESISTIU / IGOR aprovado 06/05 não deu mais retorno| CANDIDATO LUCAS APROVADO 08/05 FECHADO PELA NATHALYA | S18: RECEPTIVO NO WHATSAPP | T18: 119 7521-3162 | U18: BEATRIZ | V18: 46150 | W18: LUCAS VINICIUS MENDES DOS SANTOS | X18: ADMITIDO | Y18: 46154 | Z18: 46155 | AA18: 145949 | AB18: IGOR SANTOS - Atraso para subir , devido falta de documentos . Feito cadastro desistiu da vaga | AD18: 0
A19: 29429 | B19: 1 | C19: 46098 | D19: =TODAY()-C19 -> 129 | E19: =IF(X19="ADMITIDO","ADMITIDO",IF(X19="CANCELADA","CANCELADA",IF(H19="","",IF(H19="ADMITIDO","ADMITIDO",IF(H19="CANCELADA","CANCELADA",IF(OR(H19="ANALISE CANCELAMENTO",H19="ANÁLISE CANCELAMENTO"),"EM ANÁLISE",IF(D19="","",IF(D19<=7,"NO PRAZO",IF(D19<=14,"ATENÇÃO","CRÍTICO"))))))))) -> ADMITIDO | F19: FACILITIES | G19: WILLIAM | H19: ADMITIDO | I19: =IF(X19="ADMITIDO","ADMITIDO",IF(X19="CANCELADA","CANCELADA",IF(H19="","",IFERROR(_xlfn.XLOOKUP(H19,Listas!I:I,Listas!J:J),"OUTROS")))) -> ADMITIDO | J19: AUXILIAR DE LIMPEZA | K19: MAIARA RODRIGUES DE ANDRADE COSTA | L19: FACILITIES7 - RESERVA DELPHOS | N19: RESERVAS | O19: DIURNO | P19: 6X1 FOLGA DOM/FER | Q19: 09H - 07:00-16:00 C/INT SEG- SEX/04H S/D | R19: CANDIDATA ALYCIA EM PESQUISA 08/05 - CANDIDATA ALYCIA APROVADA 11/05 | S19: INDIQUE UM AMIGO | T19: 11 95585-2637 | U19: PATRICIA | W19: FRANCISCO PELE DE MOURA | X19: ADMITIDO | Y19: 46148 | Z19: 46149 | AA19: 145923 | AD19: 0
A20: 29429 | B20: 1 | C20: 46098 | D20: =TODAY()-C20 -> 129 | E20: =IF(X20="ADMITIDO","ADMITIDO",IF(X20="CANCELADA","CANCELADA",IF(H20="","",IF(H20="ADMITIDO","ADMITIDO",IF(H20="CANCELADA","CANCELADA",IF(OR(H20="ANALISE CANCELAMENTO",H20="ANÁLISE CANCELAMENTO"),"EM ANÁLISE",IF(D20="","",IF(D20<=7,"NO PRAZO",IF(D20<=14,"ATENÇÃO","CRÍTICO"))))))))) -> ADMITIDO | F20: FACILITIES | G20: NATHALYA | H20: ADMITIDO | I20: =IF(X20="ADMITIDO","ADMITIDO",IF(X20="CANCELADA","CANCELADA",IF(H20="","",IFERROR(_xlfn.XLOOKUP(H20,Listas!I:I,Listas!J:J),"OUTROS")))) -> ADMITIDO | J20: AUXILIAR DE LIMPEZA | K20: MAIARA RODRIGUES DE ANDRADE COSTA | L20: FACILITIES7 - RESERVA DELPHOS | N20: RESERVAS | O20: DIURNO | P20: 6X1 FOLGA DOM/FER | Q20: 09H - 07:00-16:00 C/INT SEG- SEX/04H S/D | R20: CANDIDATA ALYCIA EM PESQUISA 08/05 - CANDIDATA ALYCIA APROVADA 11/05 | S20: INDIQUE UM AMIGO | T20: 11 95585-2637 | U20: BEATRIZ | V20: 46153 | W20: ALYCIA CRISTINA VILELA | X20: ADMITIDO | Y20: 46157 | Z20: 46160 | AA20: 145975 | AD20: 0
A21: 29897 | B21: 1 | C21: 46126 | D21: =TODAY()-C21 -> 101 | E21: =IF(X21="ADMITIDO","ADMITIDO",IF(X21="CANCELADA","CANCELADA",IF(H21="","",IF(H21="ADMITIDO","ADMITIDO",IF(H21="CANCELADA","CANCELADA",IF(OR(H21="ANALISE CANCELAMENTO",H21="ANÁLISE CANCELAMENTO"),"EM ANÁLISE",IF(D21="","",IF(D21<=7,"NO PRAZO",IF(D21<=14,"ATENÇÃO","CRÍTICO"))))))))) -> ADMITIDO | F21: SEGURANÇA | G21: ANDREIA | H21: =X21 -> ADMITIDO | I21: =IF(X21="ADMITIDO","ADMITIDO",IF(X21="CANCELADA","CANCELADA",IF(H21="","",IFERROR(_xlfn.XLOOKUP(H21,Listas!I:I,Listas!J:J),"OUTROS")))) -> ADMITIDO | J21: VIGIA | K21: MARCELO RODRIGUES CARUNCHO CARNAVAL | L21: VILLA DAS ARTES | N21: SALTO | O21: DIURNO | P21: 12X36 | Q21: 12H - 06:00 - 18:00 C/ 1H INTERV | U21: ANA | V21: 46139 | W21: STEPHANE BEATRIZ DA SILVA | X21: ADMITIDO | Y21: 46141 | Z21: 46142 | AA21: 914200 | AD21: 0
A22: 29467 | B22: 1 | C22: 46099 | D22: =TODAY()-C22 -> 128 | E22: =IF(X22="ADMITIDO","ADMITIDO",IF(X22="CANCELADA","CANCELADA",IF(H22="","",IF(H22="ADMITIDO","ADMITIDO",IF(H22="CANCELADA","CANCELADA",IF(OR(H22="ANALISE CANCELAMENTO",H22="ANÁLISE CANCELAMENTO"),"EM ANÁLISE",IF(D22="","",IF(D22<=7,"NO PRAZO",IF(D22<=14,"ATENÇÃO","CRÍTICO"))))))))) -> ADMITIDO | F22: FACILITIES | G22: NATHALYA | H22: =X22 -> ADMITIDO | I22: =IF(X22="ADMITIDO","ADMITIDO",IF(X22="CANCELADA","CANCELADA",IF(H22="","",IFERROR(_xlfn.XLOOKUP(H22,Listas!I:I,Listas!J:J),"OUTROS")))) -> ADMITIDO | J22: AUXILIAR DE LIMPEZA | K22: MAIARA RODRIGUES DE ANDRADE COSTA | L22: SPAZIO BONFIGLIOLI | N22: JUNDIAÍ | O22: DIURNO | P22: 6X1 FOLGA DOM/FER | Q22: 09H - 08:00-17:00 C/INT SEG- SEX/04H SAB | R22: CANDIDATA REGINA APROVADA 20/03 (Parou de responder) - CANDIDATA ELIANA APROVADA 24/03 (Parou de responder) - CANDIDATA LUCIMAR APROVADA 13/04 | S22: WHATSAPP | T22: 11 95244-1563 | U22: RITA | V22: 46125 | W22: LUCIMAR DA SILVA PEREIRA | X22: ADMITIDO | Y22: 46132 | Z22: 46134 | AA22: 145849 | AB22: Inicio acordado com a recrutadora | AD22: 0
A23: 29800 | B23: 1 | C23: 46122 | D23: =TODAY()-C23 -> 105 | E23: =IF(X23="ADMITIDO","ADMITIDO",IF(X23="CANCELADA","CANCELADA",IF(H23="","",IF(H23="ADMITIDO","ADMITIDO",IF(H23="CANCELADA","CANCELADA",IF(OR(H23="ANALISE CANCELAMENTO",H23="ANÁLISE CANCELAMENTO"),"EM ANÁLISE",IF(D23="","",IF(D23<=7,"NO PRAZO",IF(D23<=14,"ATENÇÃO","CRÍTICO"))))))))) -> ADMITIDO | F23: FACILITIES | G23: FREITAS | H23: =X23 -> ADMITIDO | I23: =IF(X23="ADMITIDO","ADMITIDO",IF(X23="CANCELADA","CANCELADA",IF(H23="","",IFERROR(_xlfn.XLOOKUP(H23,Listas!I:I,Listas!J:J),"OUTROS")))) -> ADMITIDO | J23: AUXILIAR DE LIMPEZA | K23: KELLY ROBERTA FRATUCCI | L23: ADP BRASIL - MATRIZ SP | N23: SÃO PAULO | O23: DIURNO | P23: 6X1 FOLGA DOM/FER | Q23: 08:20H - 13:40 - 22:00 C/ 1H INTERV | U23: ROSI | V23: 46129 | W23: LIGIA CLAUDIA DA SILVA | X23: ADMITIDO | Y23: 46135 | Z23: 46136 | AA23: 914148 | AD23: 0
